<?xml version="1.0"?>
<robot xmlns:xacro="http://www.ros.org/wiki/xacro" name="kuka_kr10r1420">

  <xacro:include filename="$(find kuka_description)/resources/common_materials.xacro"/>

  <xacro:arg name="is_ignition" default="true"/>
  <xacro:include filename="$(find kuka_description)/urdf/kuka_gazebo.xacro" />
  <xacro:include filename="$(find kuka_description)/urdf/kuka_ros2_control.xacro" />

  <xacro:macro name ="default_inertial" params ="mass">
        <inertial>
            <mass value="${mass}"/>
            <inertia ixx="3.0" ixy="0.0" ixz="0.0" iyy="3.0" iyz="0.0" izz="3.0"/>
        </inertial>

    </xacro:macro>

  <xacro:macro name="kuka_kr10r1420" params="prefix">

    <link name="world" />
    <link name="${prefix}base_link">
      <xacro:default_inertial mass ="50.0" />
      <visual>
        <origin xyz="0 0 0" rpy="0 0 0"/>
        <geometry>
          <mesh filename="package://kuka_description/meshes/base_link.stl" />
        </geometry>
        <xacro:material_kuka_black />
      </visual>
      <collision>
        <origin xyz="0 0 0" rpy="0 0 0"/>
        <geometry>
          <mesh filename="package://kuka_description/collisions/base_link.stl" />
        </geometry>
      </collision>
    </link>


    <link name="${prefix}link_1">
      <xacro:default_inertial mass ="20.0" />
      <visual>
        <origin xyz="0 0 0" rpy="0 0 0"/>
        <geometry>
          <mesh filename="package://kuka_description/meshes/link_1.stl" />
        </geometry>
        <xacro:material_kuka_orange />
      </visual>
      <collision>
        <origin xyz="0 0 0" rpy="0 0 0"/>
        <geometry>
          <mesh filename="package://kuka_description/collisions/link_1.stl" />
        </geometry>
      </collision>
    </link>

    <link name="${prefix}link_2">
      <xacro:default_inertial mass ="15.0" />
      <visual>
        <origin xyz="0 0 0" rpy="0 0 0"/>
        <geometry>
          <mesh filename="package://kuka_description/meshes/link_2.stl"  />
        </geometry>
        <xacro:material_kuka_orange />
      </visual>
      <collision>
        <origin xyz="0 0 0" rpy="0 0 0"/>
        <geometry>
          <mesh filename="package://kuka_description/collisions/link_2.stl"  />
        </geometry>
      </collision>
    </link>

    <link name="${prefix}link_3">
      <xacro:default_inertial mass ="12.0" />
      <visual>
        <origin xyz="0 0 0" rpy="0 0 0"/>
        <geometry>
          <mesh filename="package://kuka_description/meshes/link_3.stl" />
        </geometry>
        <xacro:material_kuka_orange />
      </visual>
      <collision>
        <origin xyz="0 0 0" rpy="0 0 0"/>
        <geometry>
          <mesh filename="package://kuka_description/collisions/link_3.stl"  />
        </geometry>
      </collision>
    </link>

    <link name="${prefix}link_4">
      <xacro:default_inertial mass ="8.0" />
      <visual>
        <origin xyz="0 0 0" rpy="0 0 0"/>
        <geometry>
          <mesh filename="package://kuka_description/meshes/link_4.stl"  />
        </geometry>
        <xacro:material_kuka_orange />
      </visual>
      <collision>
        <origin xyz="0 0 0" rpy="0 0 0"/>
        <geometry>
          <mesh filename="package://kuka_description/collisions/link_4.stl" />
        </geometry>
      </collision>
    </link>

    <link name="${prefix}link_5">
      <xacro:default_inertial mass ="5.0" />
      <visual>
        <origin xyz="0 0 0" rpy="0 0 0"/>
        <geometry>
          <mesh filename="package://kuka_description/meshes/link_5.stl" />
        </geometry>
        <xacro:material_kuka_orange />
      </visual>
      <collision>
        <origin xyz="0 0 0" rpy="0 0 0"/>
        <geometry>
          <mesh filename="package://kuka_description/collisions/link_5.stl"  />
        </geometry>
      </collision>
    </link>

    <link name="${prefix}link_6">
      <xacro:default_inertial mass ="3.0" />
      <visual>
        <origin xyz="0 0 0" rpy="0 0 0"/>
        <geometry>
          <mesh filename="package://kuka_description/meshes/link_6.stl"  />
        </geometry>
        <xacro:material_kuka_pedestal />
      </visual>
      <collision>
        <origin xyz="0 0 0" rpy="0 0 0"/>
        <geometry>
          <mesh filename="package://kuka_description/collisions/link_6.stl"  />
        </geometry>
      </collision>
    </link>

    <!-- Following REP199, this frame shall be used to attach EEF or other equipment -->
    <link name="${prefix}flange" />

    <joint name="virtual_joint" type="fixed">
      <parent link="world"/>
      <child link="${prefix}base_link"/>
      <origin rpy = "0 0 0" xyz = "0 0 0"/>
  
    </joint>  

    <joint name="${prefix}joint_a1" type="revolute">
      <origin xyz="0 0 0.450" rpy="0 0 0"/>
      <parent link="${prefix}base_link"/>
      <child link="${prefix}link_1"/>
      <axis xyz="0 0 -1"/>
      <limit effort="200" lower="${radians(-170)}" upper="${radians(170)}" velocity="${radians(220)}"/>
    </joint>

    <joint name="${prefix}joint_a2" type="revolute">
      <origin xyz="0.150 0 0" rpy="0 0 0"/>
      <parent link="${prefix}link_1"/>
      <child link="${prefix}link_2"/>
      <axis xyz="0 1 0"/>
      <limit effort="500" lower="${radians(-185)}" upper="${radians(65)}" velocity="${radians(210)}"/>
    </joint>

    <joint name="${prefix}joint_a3" type="revolute">
      <origin xyz="0.610 0 0" rpy="0 0 0"/>
      <parent link="${prefix}link_2"/>
      <child link="${prefix}link_3"/>
      <axis xyz="0 1 0"/>
      <limit effort="300" lower="${radians(-137)}" upper="${radians(163)}" velocity="${radians(270)}"/>
    </joint>

    <joint name="${prefix}joint_a4" type="revolute">
      <origin xyz="0 0 0.02" rpy="0 0 0"/>
      <parent link="${prefix}link_3"/>
      <child link="${prefix}link_4"/>
      <axis xyz="-1 0 0"/>
      <limit effort="200" lower="${radians(-185)}" upper="${radians(185)}" velocity="${radians(381)}"/>
    </joint>

    <joint name="${prefix}joint_a5" type="revolute">
      <origin xyz="0.660 0 0" rpy="0 0 0"/>
      <parent link="${prefix}link_4"/>
      <child link="${prefix}link_5"/>
      <axis xyz="0 1 0"/>
      <limit effort="155" lower="${radians(-120)}" upper="${radians(120)}" velocity="${radians(311)}"/>
    </joint>

    <joint name="${prefix}joint_a6" type="revolute">
      <origin xyz="0.080 0 0" rpy="0 0 0"/>
      <parent link="${prefix}link_5"/>
      <child link="${prefix}link_6"/>
      <axis xyz="-1 0 0"/>
      <limit effort="100" lower="${radians(-350)}" upper="${radians(350)}" velocity="${radians(492)}"/>
    </joint>

    <joint name="${prefix}joint_a6-flange" type="fixed">
      <parent link="${prefix}link_6"/>
      <child link="${prefix}flange"/>
      <origin xyz="0 0 0" rpy="0 0 0"/>
    </joint>

    <!-- ROS base_link to KUKA $ROBROOT coordinate system transform -->
    <link name="${prefix}base" />
    <joint name="${prefix}base_link-base" type="fixed">
      <origin xyz="0 0 0" rpy="0 0 0"/>
      <parent link="${prefix}base_link"/>
      <child link="${prefix}base"/>
    </joint>

    <!-- This frame corresponds to the $TOOL coordinate system in KUKA KRC controllers -->
    <link name="${prefix}tool0" />
    <joint name="${prefix}flange-tool0" type="fixed">
      <parent link="${prefix}flange"/>
      <child link="${prefix}tool0"/>
      <origin xyz="0 0 0" rpy="0 ${radians(90)} 0"/>
    </joint>
  </xacro:macro>

  <!-- Instantiate the macro once to create the robot -->
  <xacro:kuka_kr10r1420 prefix=""/>

</robot>
